Workbook

Sheet Lead Data
A1: Lead ID | B1: Date Received | C1: Company Name | D1: Contact Person | E1: Email | F1: Lead Owner | G1: Acquisition Channel | H1: Lead Stage | I1: Priority | J1: Deal Value ($) | K1: Last Contact Date | L1: Days Since Last Contact | M1: Next Action | N1: Target Close Date
A2: L-1001 | B2: 46216 | C2: Acme Corp | D2: Arthur Pendelton | E2: arthur@acme.co | F2: Sarah Jenkins | G2: LinkedIn | H2: Closed Won | I2: High | J2: 75000 | K2: 46216 | L2: =IF(OR(H2="Closed Won",H2="Closed Lost"), "-", DATE(2026,7,14)-K2) -> 0 | M2: Account Handover | N2: -
A3: L-1002 | B3: 46214 | C3: BetaLabs | D3: Clara Oswald | E3: ap@betalabs.io | F3: David Chen | G3: LinkedIn | H3: Proposal | I3: High | J3: 24000 | K3: 46213 | L3: =IF(OR(H3="Closed Won",H3="Closed Lost"), "-", DATE(2026,7,14)-K3) -> 0 | M3: Send contract addendum | N3: 46232
A4: L-1003 | B4: 46212 | C4: Apex Logistics | D4: Kenji Sato | E4: kenji@apexlog.com | F4: Marcus Vance | G4: Partner | H4: Qualified | I4: Medium | J4: 120000 | K4: 46215 | L4: =IF(OR(H4="Closed Won",H4="Closed Lost"), "-", DATE(2026,7,14)-K4) -> 0 | M4: Schedule NetSuite demo | N4: 46277
A5: L-1004 | B5: 46211 | C5: CyberShield | D5: Evelyn Reed | E5: e.reed@cybershield.net | F5: Chloe Patel | G5: Google Search | H5: Closed Won | I5: High | J5: 45000 | K5: 46212 | L5: =IF(OR(H5="Closed Won",H5="Closed Lost"), "-", DATE(2026,7,14)-K5) -> 0 | M5: Integrate banking API | N5: -
A6: L-1005 | B6: 46209 | C6: Vortex Media | D6: Liam Carter | E6: liam@vortex.media | F6: David Chen | G6: Cold Outreach | H6: Negotiation | I6: High | J6: 35000 | K6: 46201 | L6: =IF(OR(H6="Closed Won",H6="Closed Lost"), "-", DATE(2026,7,14)-K6) -> 0 | M6: Follow up on credit terms | N6: 46227
A7: L-1006 | B7: 46207 | C7: Zeta Retail | D7: Sofia Martinez | E7: sofia@zetaretail.com | F7: Sarah Jenkins | G7: Referral | H7: New | I7: Medium | J7: 18000 | K7: 46207 | L7: =IF(OR(H7="Closed Won",H7="Closed Lost"), "-", DATE(2026,7,14)-K7) -> 0 | M7: Initial discovery call | N7: 46262
A8: L-1007 | B8: 46205 | C8: Quantum AI | D8: Ryan Sterling | E8: sterling@quantum.ai | F8: Chloe Patel | G8: Webinars | H8: Closed Lost | I8: Medium | J8: 65000 | K8: 46213 | L8: =IF(OR(H8="Closed Won",H8="Closed Lost"), "-", DATE(2026,7,14)-K8) -> 0 | M8: Lost to competitor | N8: -
A9: L-1008 | B9: 46205 | C9: CloudNexus | D9: Nolan Vance | E9: nolan@cloudnexus.io | F9: Marcus Vance | G9: Google Search | H9: Contacted | I9: High | J9: 50000 | K9: 46203 | L9: =IF(OR(H9="Closed Won",H9="Closed Lost"), "-", DATE(2026,7,14)-K9) -> 0 | M9: Send pricing matrix | N9: 46247
A10: L-1009 | B10: 46203 | C10: BioSphere | D10: Elena Rostova | E10: elena@biosphere.org | F10: Sarah Jenkins | G10: LinkedIn | H10: Closed Won | I10: Medium | J10: 28000 | K10: 46215 | L10: =IF(OR(H10="Closed Won",H10="Closed Lost"), "-", DATE(2026,7,14)-K10) -> 0 | M10: Set up corporate cards | N10: -
A11: L-1010 | B11: 46202 | C11: Nova Fleet | D11: Devon Cole | E11: d.cole@novafleet.co | F11: David Chen | G11: Cold Outreach | H11: Proposal | I11: High | J11: 85000 | K11: 46205 | L11: =IF(OR(H11="Closed Won",H11="Closed Lost"), "-", DATE(2026,7,14)-K11) -> 0 | M11: Review custom card request | N11: 46229
A12: L-1011 | B12: 46201 | C12: InnoTech | D12: Marcus Aurelius | E12: marcus@innotech.it | F12: Marcus Vance | G12: Referral | H12: Negotiation | I12: High | J12: 95000 | K12: 46199 | L12: =IF(OR(H12="Closed Won",H12="Closed Lost"), "-", DATE(2026,7,14)-K12) -> 0 | M12: Approve billing agreement | N12: 46224
A13: L-1012 | B13: 46199 | C13: Echo Travel | D13: Zoe Washburne | E13: zoe@echotravel.com | F13: Sarah Jenkins | G13: Google Search | H13: Closed Won | I13: Low | J13: 15000 | K13: 46216 | L13: =IF(OR(H13="Closed Won",H13="Closed Lost"), "-", DATE(2026,7,14)-K13) -> 0 | M13: Completed onboarding | N13: -
A14: L-1013 | B14: 46197 | C14: Delta FinTech | D14: Silas Stone | E14: stone@deltafin.io | F14: Chloe Patel | G14: Partner | H14: Contacted | I14: High | J14: 110000 | K14: 46202 | L14: =IF(OR(H14="Closed Won",H14="Closed Lost"), "-", DATE(2026,7,14)-K14) -> 0 | M14: Resend security whitepaper | N14: 46252
A15: L-1014 | B15: 46196 | C15: Titan Heavy | D15: Sarah Connor | E15: connor@titanheavy.com | F15: Marcus Vance | G15: Cold Outreach | H15: New | I15: Low | J15: 60000 | K15: 46196 | L15: =IF(OR(H15="Closed Won",H15="Closed Lost"), "-", DATE(2026,7,14)-K15) -> 0 | M15: Book intro meeting | N15: 46277
A16: L-1015 | B16: 46195 | C16: Matrix Group | D16: Thomas Anderson | E16: neo@matrix.co | F16: David Chen | G16: LinkedIn | H16: Proposal | I16: Medium | J16: 40000 | K16: 46209 | L16: =IF(OR(H16="Closed Won",H16="Closed Lost"), "-", DATE(2026,7,14)-K16) -> 0 | M16: Send custom integration quote | N16: 46237
A17: L-1016 | B17: 46193 | C17: Solaris Energy | D17: Dr. Kelvin | E17: kelvin@solaris.org | F17: Sarah Jenkins | G17: Webinars | H17: Closed Lost | I17: Low | J17: 30000 | K17: 46207 | L17: =IF(OR(H17="Closed Won",H17="Closed Lost"), "-", DATE(2026,7,14)-K17) -> 0 | M17: Budget constraints | N17: -
A18: L-1017 | B18: 46192 | C18: Starlight Corp | D18: Jane Doe | E18: jane@starlight.com | F18: Chloe Patel | G18: Google Search | H18: Closed Won | I18: Medium | J18: 52000 | K18: 46212 | L18: =IF(OR(H18="Closed Won",H18="Closed Lost"), "-", DATE(2026,7,14)-K18) -> 0 | M18: Onboarding session 1 | N18: -
A19: L-1018 | B19: 46191 | C19: Omega Health | D19: James Watson | E19: watson@omega.health | F19: David Chen | G19: Referral | H19: Contacted | I19: Medium | J19: 22000 | K19: 46205 | L19: =IF(OR(H19="Closed Won",H19="Closed Lost"), "-", DATE(2026,7,14)-K19) -> 0 | M19: Follow up after demo | N19: 46245
A20: L-1019 | B20: 46189 | C20: Beacon Tech | D20: Bruce Wayne | E20: bruce@beacon.com | F20: Marcus Vance | G20: LinkedIn | H20: Proposal | I20: High | J20: 140000 | K20: 46197 | L20: =IF(OR(H20="Closed Won",H20="Closed Lost"), "-", DATE(2026,7,14)-K20) -> 0 | M20: Finalize card limit terms | N20: 46225
A21: L-1020 | B21: 46187 | C21: Astra Pharma | D21: Clara Barton | E21: barton@astrapharma.com | F21: Sarah Jenkins | G21: Partner | H21: Qualified | I21: Low | J21: 70000 | K21: 46210 | L21: =IF(OR(H21="Closed Won",H21="Closed Lost"), "-", DATE(2026,7,14)-K21) -> 0 | M21: Send API docs | N21: 46267
A22: L-1021 | B22: 46186 | C22: Prime Movers | D22: Tony Stark | E22: stark@primemovers.io | F22: Chloe Patel | G22: Cold Outreach | H22: New | I22: High | J22: 90000 | K22: 46186 | L22: =IF(OR(H22="Closed Won",H22="Closed Lost"), "-", DATE(2026,7,14)-K22) -> 0 | M22: Cold call follow-up | N22: 46307
A23: L-1022 | B23: 46185 | C23: Atlas Global | D23: Diana Prince | E23: diana@atlas.org | F23: David Chen | G23: Google Search | H23: Closed Won | I23: High | J23: 130000 | K23: 46215 | L23: =IF(OR(H23="Closed Won",H23="Closed Lost"), "-", DATE(2026,7,14)-K23) -> 0 | M23: Activate multi-currency | N23: -
A24: L-1023 | B24: 46182 | C24: Vanguard Law | D24: Harvey Specter | E24: specter@vanguard.law | F24: Marcus Vance | G24: Referral | H24: Negotiation | I24: High | J24: 80000 | K24: 46202 | L24: =IF(OR(H24="Closed Won",H24="Closed Lost"), "-", DATE(2026,7,14)-K24) -> 0 | M24: Schedule legal review | N24: 46222
A25: L-1024 | B25: 46181 | C25: Element Designs | D25: Peter Parker | E25: peter@element.co | F25: Sarah Jenkins | G25: LinkedIn | H25: Contacted | I25: Low | J25: 12000 | K25: 46211 | L25: =IF(OR(H25="Closed Won",H25="Closed Lost"), "-", DATE(2026,7,14)-K25) -> 0 | M25: Send corporate card deck | N25: 46257
A26: L-1025 | B26: 46179 | C26: Summit Ventures | D26: Lara Croft | E26: lara@summit.org | F26: Chloe Patel | G26: Webinars | H26: Qualified | I26: Medium | J26: 55000 | K26: 46209 | L26: =IF(OR(H26="Closed Won",H26="Closed Lost"), "-", DATE(2026,7,14)-K26) -> 0 | M26: Schedule platform demo | N26: 46252
A27: L-1026 | B27: 46177 | C27: Nexus Freight | D27: Han Solo | E27: han@nexusfreight.com | F27: Marcus Vance | G27: Partner | H27: Closed Lost | I27: High | J27: 115000 | K27: 46212 | L27: =IF(OR(H27="Closed Won",H27="Closed Lost"), "-", DATE(2026,7,14)-K27) -> 0 | M27: Lost to local provider | N27: -
A28: L-1027 | B28: 46175 | C28: Prism Creative | D28: Iris West | E28: iris@prism.io | F28: David Chen | G28: Google Search | H28: Closed Won | I28: Medium | J28: 25000 | K28: 46216 | L28: =IF(OR(H28="Closed Won",H28="Closed Lost"), "-", DATE(2026,7,14)-K28) -> 0 | M28: Completed onboarding | N28: -
A29: L-1028 | B29: 46173 | C29: Helix Labs | D29: Walter Bishop | E29: walter@helixlabs.co | F29: Sarah Jenkins | G29: LinkedIn | H29: Negotiation | I29: Medium | J29: 60000 | K29: 46208 | L29: =IF(OR(H29="Closed Won",H29="Closed Lost"), "-", DATE(2026,7,14)-K29) -> 0 | M29: Send updated bill pay pricing | N29: 46231
A30: L-1029 | B30: 46172 | C30: Infinity Retail | D30: Wanda Maximoff | E30: wanda@infinity.com | F30: Chloe Patel | G30: Cold Outreach | H30: New | I30: Medium | J30: 32000 | K30: 46172 | L30: =IF(OR(H30="Closed Won",H30="Closed Lost"), "-", DATE(2026,7,14)-K30) -> 0 | M30: Try alternative contact | N30: 46292
A31: L-1030 | B31: 46172 | C31: Apex Builders | D31: Bob Builder | E31: bob@apexbuilders.io | F31: Marcus Vance | G31: Referral | H31: Closed Won | I31: Low | J31: 45000 | K31: 46214 | L31: =IF(OR(H31="Closed Won",H31="Closed Lost"), "-", DATE(2026,7,14)-K31) -> 0 | M31: Account set up finished | N31: -
A32: L-1031 | B32: 46171 | C32: Core Consulting | D32: Arthur Dent | E32: dent@coreconsult.com | F32: David Chen | G32: Google Search | H32: Proposal | I32: Low | J32: 20000 | K32: 46203 | L32: =IF(OR(H32="Closed Won",H32="Closed Lost"), "-", DATE(2026,7,14)-K32) -> 0 | M32: Send customized proposal | N32: 46238
A33: L-1032 | B33: 46169 | C33: Stellar Ops | D33: Carol Danvers | E33: carol@stellarops.net | F33: Sarah Jenkins | G33: Partner | H33: Closed Won | I33: High | J33: 105000 | K33: 46216 | L33: =IF(OR(H33="Closed Won",H33="Closed Lost"), "-", DATE(2026,7,14)-K33) -> 0 | M33: Assign card manager roles | N33: -
A34: L-1033 | B34: 46167 | C34: Zephyr Aviation | D34: Hal Jordan | E34: jordan@zephyrav.com | F34: Chloe Patel | G34: LinkedIn | H34: Closed Lost | I34: Medium | J34: 95000 | K34: 46214 | L34: =IF(OR(H34="Closed Won",H34="Closed Lost"), "-", DATE(2026,7,14)-K34) -> 0 | M34: Internal delay, deferred | N34: -
A35: L-1034 | B35: 46165 | C35: Horizon Media | D35: Barry Allen | E35: barry@horizon.com | F35: Marcus Vance | G35: Cold Outreach | H35: Contacted | I35: High | J35: 48000 | K35: 46192 | L35: =IF(OR(H35="Closed Won",H35="Closed Lost"), "-", DATE(2026,7,14)-K35) -> 0 | M35: Schedule follow-up call | N35: 46247
A36: L-1035 | B36: 46162 | C36: Alpha Security | D36: John McClane | E36: john@alphasec.io | F36: David Chen | G36: Google Search | H36: Qualified | I36: Low | J36: 38000 | K36: 46207 | L36: =IF(OR(H36="Closed Won",H36="Closed Lost"), "-", DATE(2026,7,14)-K36) -> 0 | M36: Send compliance checklist | N36: 46262
A37: L-1036 | B37: 46161 | C37: Pioneer Biotech | D37: Reed Richards | E37: reed@pioneerbio.org | F37: Sarah Jenkins | G37: Referral | H37: Closed Won | I37: High | J37: 125000 | K37: 46215 | L37: =IF(OR(H37="Closed Won",H37="Closed Lost"), "-", DATE(2026,7,14)-K37) -> 0 | M37: Setup NetSuite ERP integration | N37: -
A38: L-1037 | B38: 46159 | C38: Falcon Logistics | D38: Sam Wilson | E38: sam@falcon.com | F38: Chloe Patel | G38: Partner | H38: New | I38: Low | J38: 72000 | K38: 46159 | L38: =IF(OR(H38="Closed Won",H38="Closed Lost"), "-", DATE(2026,7,14)-K38) -> 0 | M38: Introductory email | N38: 46307
A39: L-1038 | B39: 46157 | C39: Silver Lining | D39: Bruce Banner | E39: banner@silverlining.org | F39: Marcus Vance | G39: LinkedIn | H39: Closed Won | I39: Medium | J39: 50000 | K39: 46213 | L39: =IF(OR(H39="Closed Won",H39="Closed Lost"), "-", DATE(2026,7,14)-K39) -> 0 | M39: Complete setup call | N39: -
A40: L-1039 | B40: 46157 | C40: Genesis Digital | D40: Charles Xavier | E40: xavier@genesis.edu | F40: David Chen | G40: Webinars | H40: Proposal | I40: Medium | J40: 42000 | K40: 46206 | L40: =IF(OR(H40="Closed Won",H40="Closed Lost"), "-", DATE(2026,7,14)-K40) -> 0 | M40: Follow up on invoice matching questions | N40: 46242
...

Sheet Dashboard
B1: SALES PIPELINE & LEAD MANAGEMENT DASHBOARD
B2: Volopay Growth Squad Operational Console — Generated July 14, 2026
B4: TOTAL LEADS RECEIVED | D4: CLOSED WON DEALS | F4: CONVERSION / WIN RATE | H4: ACTIVE PIPELINE VALUE | J4: HIGH PRIORITY STALE (>10d) | L4: TOTAL WON REVENUE (ARR)
B5: =COUNTA('Lead Data'!A2:A51) -> 0 | D5: =COUNTIF('Lead Data'!H2:H51, "Closed Won") -> 0 | F5: =D5/B5 -> 0 | H5: =SUMIFS('Lead Data'!J2:J51, 'Lead Data'!H2:H51, "<>Closed Lost", 'Lead Data'!H2:H51, "<>Closed Won") -> 0 | J5: =COUNTIFS('Lead Data'!I2:I51, "High", 'Lead Data'!H2:H51, "<>Closed Won", 'Lead Data'!H2:H51, "<>Closed Lost", 'Lead Data'!L2:L51, ">10") -> 0 | L5: =SUMIF('Lead Data'!H2:H51, "Closed Won", 'Lead Data'!J2:J51) -> 0
B8: Acquisition Channel Performance | F8: Pipeline Stage Distribution
B9: Channel | C9: Leads Count | D9: Won Revenue | F9: Lead Stage | G9: Deals Count | H9: Total Value
B10: LinkedIn | C10: =COUNTIF('Lead Data'!G$2:G$51, B10) -> 0 | D10: =SUMIFS('Lead Data'!J$2:J$51, 'Lead Data'!G$2:G$51, B10, 'Lead Data'!H$2:H$51, "Closed Won") -> 0 | F10: New | G10: =COUNTIF('Lead Data'!H$2:H$51, F10) -> 0 | H10: =SUMIF('Lead Data'!H$2:H$51, F10, 'Lead Data'!J$2:J$51) -> 0
B11: Google Search | C11: =COUNTIF('Lead Data'!G$2:G$51, B11) -> 0 | D11: =SUMIFS('Lead Data'!J$2:J$51, 'Lead Data'!G$2:G$51, B11, 'Lead Data'!H$2:H$51, "Closed Won") -> 0 | F11: Contacted | G11: =COUNTIF('Lead Data'!H$2:H$51, F11) -> 0 | H11: =SUMIF('Lead Data'!H$2:H$51, F11, 'Lead Data'!J$2:J$51) -> 0
B12: Cold Outreach | C12: =COUNTIF('Lead Data'!G$2:G$51, B12) -> 0 | D12: =SUMIFS('Lead Data'!J$2:J$51, 'Lead Data'!G$2:G$51, B12, 'Lead Data'!H$2:H$51, "Closed Won") -> 0 | F12: Qualified | G12: =COUNTIF('Lead Data'!H$2:H$51, F12) -> 0 | H12: =SUMIF('Lead Data'!H$2:H$51, F12, 'Lead Data'!J$2:J$51) -> 0
B13: Referral | C13: =COUNTIF('Lead Data'!G$2:G$51, B13) -> 0 | D13: =SUMIFS('Lead Data'!J$2:J$51, 'Lead Data'!G$2:G$51, B13, 'Lead Data'!H$2:H$51, "Closed Won") -> 0 | F13: Proposal | G13: =COUNTIF('Lead Data'!H$2:H$51, F13) -> 0 | H13: =SUMIF('Lead Data'!H$2:H$51, F13, 'Lead Data'!J$2:J$51) -> 0
B14: Partner | C14: =COUNTIF('Lead Data'!G$2:G$51, B14) -> 0 | D14: =SUMIFS('Lead Data'!J$2:J$51, 'Lead Data'!G$2:G$51, B14, 'Lead Data'!H$2:H$51, "Closed Won") -> 0 | F14: Negotiation | G14: =COUNTIF('Lead Data'!H$2:H$51, F14) -> 0 | H14: =SUMIF('Lead Data'!H$2:H$51, F14, 'Lead Data'!J$2:J$51) -> 0
B15: Webinars | C15: =COUNTIF('Lead Data'!G$2:G$51, B15) -> 0 | D15: =SUMIFS('Lead Data'!J$2:J$51, 'Lead Data'!G$2:G$51, B15, 'Lead Data'!H$2:H$51, "Closed Won") -> 0 | F15: Closed Won | G15: =COUNTIF('Lead Data'!H$2:H$51, F15) -> 0 | H15: =SUMIF('Lead Data'!H$2:H$51, F15, 'Lead Data'!J$2:J$51) -> 0
B16: Total | C16: =SUM(C10:C15) -> 0 | D16: =SUM(D10:D15) -> 0 | F16: Closed Lost | G16: =COUNTIF('Lead Data'!H$2:H$51, F16) -> 0 | H16: =SUMIF('Lead Data'!H$2:H$51, F16, 'Lead Data'!J$2:J$51) -> 0
F17: Total | G17: =SUM(G10:G16) -> 0 | H17: =SUM(H10:H16) -> 0
B19: Urgent Action Items: Neglected & High-Priority Open Leads
B20: Company Name | C20: Lead Owner | D20: Deal Value ($) | E20: Days Stale | F20: Priority | G20: Recommended Action
B21: Jotunheim Cooling | C21: Marcus Vance | D21: 80000 | E21: 90 | F21: High | G21: Re-attempt call with manager
B22: Hyperion Systems | C22: Marcus Vance | D22: 67000 | E22: 75 | F22: Medium | G22: Cold outreach call
B23: Infinity Retail | C23: Chloe Patel | D23: 32000 | E23: 45 | F23: Medium | G23: Try alternative contact
B24: Prime Movers | C24: Chloe Patel | D24: 90000 | E24: 31 | F24: High | G24: Cold call follow-up
B25: Horizon Media | C25: Marcus Vance | D25: 48000 | E25: 25 | F25: High | G25: Schedule follow-up call
